<?xml version="1.0" ?>
<!-- =================================================================================== -->
<!-- |    This document was autogenerated by xacro from deepracer.xacro                | -->
<!-- |    EDITING THIS FILE BY HAND IS NOT RECOMMENDED                                 | -->
<!-- =================================================================================== -->
<!--
Copyright Amazon.com, Inc. or its affiliates. All Rights Reserved.

Licensed under the Apache License, Version 2.0 (the "License").
You may not use this file except in compliance with the License.
You may obtain a copy of the License at

    http://www.apache.org/licenses/LICENSE-2.0

Unless required by applicable law or agreed to in writing, software
distributed under the License is distributed on an "AS IS" BASIS,
WITHOUT WARRANTIES OR CONDITIONS OF ANY KIND, either express or implied.
See the License for the specific language governing permissions and
limitations under the License.
-->
<robot name="racecar">
  <link name="base_link"/>
  <link name="chassis">
    <inertial>
      <origin rpy="0 0 0" xyz="0 0 0"/>
      <mass value="1.9068"/>
      <inertia ixx="0.004151895" ixy="0" ixz="0" iyy="0.010379737" iyz="0" izz="0.010379737"/>
    </inertial>
  </link>
  <joint name="base_link_joint" type="fixed">
    <origin rpy="0 0 0" xyz="0 0 0.023249"/>
    <parent link="base_link"/>
    <child link="chassis"/>
  </joint>
  <link name="left_rear_wheel">
    <inertial>
      <origin rpy="0 1.5707 1.5707" xyz="0 0 0"/>
      <mass value="0.042222"/>
      <inertia ixx="0.0000611771" ixy="0" ixz="0" iyy="0.0000611771" iyz="0" izz="0.0000944606"/>
    </inertial>
    <visual>
      <origin rpy="0 1.5707 1.5707" xyz="0 0 0"/>
      <geometry>
        <cylinder length="0.025" radius="0.03"/>
      </geometry>
    </visual>
    <collision>
      <origin rpy="0 1.5707 1.5707" xyz="0 0 0"/>
      <geometry>
        <cylinder length="0.025" radius="0.03"/>
      </geometry>
    </collision>
  </link>
  <joint name="left_rear_wheel_joint" type="continuous">
    <origin rpy="0 0 0" xyz="-0.081663 0.08105 0.01575"/>
    <parent link="chassis"/>
    <child link="left_rear_wheel"/>
    <axis xyz="0 1 0"/>
    <limit effort="10" lower="-1" upper="1" velocity="100"/>
  </joint>
  <link name="right_rear_wheel">
    <inertial>
      <origin rpy="0 1.5707 1.5707" xyz="0 0 0"/>
      <mass value="0.042222"/>
      <inertia ixx="0.0000611771" ixy="0" ixz="0" iyy="0.0000611771" iyz="0" izz="0.0000944606"/>
    </inertial>
    <visual>
      <origin rpy="0 1.5707 1.5707" xyz="0 0 0"/>
      <geometry>
        <cylinder length="0.025" radius="0.03"/>
      </geometry>
    </visual>
    <collision>
      <origin rpy="0 1.5707 1.5707" xyz="0 0 0"/>
      <geometry>
        <cylinder length="0.025" radius="0.03"/>
      </geometry>
    </collision>
  </link>
  <joint name="right_rear_wheel_joint" type="continuous">
    <origin rpy="0 0 0" xyz="-0.081663 -0.08105 0.01575"/>
    <parent link="chassis"/>
    <child link="right_rear_wheel"/>
    <axis xyz="0 1 0"/>
    <limit effort="10" lower="-1" upper="1" velocity="100"/>
  </joint>
  <link name="left_steering_hinge">
    <inertial>
      <origin rpy="0 0 0" xyz="0 0 0"/>
      <mass value="0.050"/>
      <inertia ixx="4E-06" ixy="0" ixz="0" iyy="4E-06" iyz="0" izz="4E-06"/>
    </inertial>
    <visual>
      <origin rpy="0 0 0" xyz="0 0 0"/>
      <geometry>
        <mesh filename="file://$(find track_model)/meshes/left_steering_hinge.STL"/>
      </geometry>
    </visual>
  </link>
  <joint name="left_steering_hinge_joint" type="continuous">
    <origin rpy="0 0 0" xyz="0.082311 0.079601 0.011759"/>
    <parent link="chassis"/>
    <child link="left_steering_hinge"/>
    <axis xyz="0 0 1"/>
    <limit effort="10" lower="-1" upper="1" velocity="100"/>
  </joint>
  <link name="left_front_wheel">
    <inertial>
      <origin rpy="0 1.5707 1.5707" xyz="0 0 0"/>
      <mass value="0.042222"/>
      <inertia ixx="0.0000611771" ixy="0" ixz="0" iyy="0.0000611771" iyz="0" izz="0.0000944606"/>
    </inertial>
    <visual>
      <origin rpy="0 1.5707 1.5707" xyz="0 0 0"/>
      <geometry>
        <cylinder length="0.025" radius="0.03"/>
      </geometry>
    </visual>
    <collision>
      <origin rpy="0 1.5707 1.5707" xyz="0 0 0"/>
      <geometry>
        <cylinder length="0.025" radius="0.03"/>
      </geometry>
    </collision>
  </link>
  <joint name="left_front_wheel_joint" type="continuous">
    <origin rpy="0 0 0" xyz="0 0 0"/>
    <parent link="left_steering_hinge"/>
    <child link="left_front_wheel"/>
    <axis xyz="0 1 0"/>
    <limit effort="10" lower="-1" upper="1" velocity="100"/>
  </joint>
  <link name="right_steering_hinge">
    <inertial>
      <origin rpy="0 0 0" xyz="0 0 0"/>
      <mass value="0.050"/>
      <inertia ixx="4E-06" ixy="0" ixz="0" iyy="4E-06" iyz="0" izz="4E-06"/>
    </inertial>
    <visual>
      <origin rpy="0 0 0" xyz="0 0 0"/>
      <geometry>
        <mesh filename="file://$(find track_model)/meshes/right_steering_hinge.STL"/>
      </geometry>
    </visual>
  </link>
  <joint name="right_steering_hinge_joint" type="continuous">
    <origin rpy="0 0 0" xyz="0.082311 -0.079601 0.011759"/>
    <parent link="chassis"/>
    <child link="right_steering_hinge"/>
    <axis xyz="0 0 1"/>
    <limit effort="10" lower="-1" upper="1" velocity="100"/>
  </joint>
  <link name="right_front_wheel">
    <inertial>
      <origin rpy="0 1.5707 1.5707" xyz="0 0 0"/>
      <mass value="0.042222"/>
      <inertia ixx="0.0000611771" ixy="0" ixz="0" iyy="0.0000611771" iyz="0" izz="0.0000944606"/>
    </inertial>
    <visual>
      <origin rpy="0 1.5707 1.5707" xyz="0 0 0"/>
      <geometry>
        <cylinder length="0.025" radius="0.03"/>
      </geometry>
    </visual>
    <collision>
      <origin rpy="0 1.5707 1.5707" xyz="0 0 0"/>
      <geometry>
        <cylinder length="0.025" radius="0.03"/>
      </geometry>
    </collision>
  </link>
  <joint name="right_front_wheel_joint" type="continuous">
    <origin rpy="0 0 0" xyz="0 0 0"/>
    <parent link="right_steering_hinge"/>
    <child link="right_front_wheel"/>
    <axis xyz="0 1 0"/>
    <limit effort="10" lower="-1" upper="1" velocity="100"/>
  </joint>
  <link name="zed_camera_link">
    <inertial>
      <origin rpy="0 0 0" xyz="0.019881 0 0.034966"/>
      <mass value="0.001"/>
      <inertia ixx="1E-06" ixy="0" ixz="0" iyy="1E-06" iyz="0" izz="1E-06"/>
    </inertial>
    <visual>
      <origin rpy="0 0 0" xyz="0 0 0"/>
      <geometry>
        <mesh filename="file://$(find track_model)/meshes/zed_camera_link.STL"/>
      </geometry>
    </visual>
  </link>
  <joint name="zed_camera_joint" type="fixed">
    <origin rpy="0 0.2618 0" xyz="0.091711 0 0.080023"/>
    <parent link="chassis"/>
    <child link="zed_camera_link"/>
    <axis xyz="0 0 0"/>
  </joint>
  <link name="camera_link">
    <inertial>
      <origin rpy="0 0 0" xyz="0.0005 0 0"/>
      <mass value="0.001"/>
      <inertia ixx="1E-06" ixy="0" ixz="0" iyy="1E-06" iyz="0" izz="1E-06"/>
    </inertial>
  </link>
  <joint name="camera_joint" type="fixed">
    <origin rpy="0 0 0" xyz="0.044755 0 0.04"/>
    <parent link="zed_camera_link"/>
    <child link="camera_link"/>
    <axis xyz="0 0 0"/>
  </joint>
  <link name="laser">
    <inertial>
      <origin rpy="0 0 0" xyz="0.006099 0.00028423 -0.012654"/>
      <mass value="1E-05"/>
      <inertia ixx="1E-06" ixy="0" ixz="0" iyy="1E-06" iyz="0" izz="1E-06"/>
    </inertial>
    <visual>
      <origin rpy="0 0 0" xyz="0 0 0"/>
      <geometry>
        <mesh filename="file://$(find track_model)/meshes/laser.STL"/>
      </geometry>
    </visual>
    <collision>
      <origin rpy="0 0 0" xyz="0 0 0"/>
      <geometry>
        <mesh filename="file://$(find track_model)/meshes/laser.STL"/>
      </geometry>
    </collision>
  </link>
  <joint name="hokuyo_joint" type="fixed">
    <origin rpy="0 0 3.1416" xyz="0.02913 0 0.16145"/>
    <parent link="chassis"/>
    <child link="laser"/>
    <axis xyz="0 0 0"/>
  </joint>
  <link name="shell">
    <inertial>
      <origin rpy="0 0 0" xyz="0 0 0"/>
      <mass value="0"/>
      <inertia ixx="0" ixy="0" ixz="0" iyy="0" iyz="0" izz="0"/>
    </inertial>
    <visual>
      <origin rpy="0 0 0" xyz="0 0 0"/>
      <geometry>
        <mesh filename="file://$(find track_model)/meshes/deepracer.STL"/>
      </geometry>
    </visual>
    <collision>
      <origin rpy="0 0 0" xyz="0 0 0"/>
      <geometry>
        <mesh filename="file://$(find track_model)/meshes/deepracer.STL"/>
      </geometry>
    </collision>
  </link>
  <joint name="shell_joint" type="fixed">
    <origin rpy="0 0 0" xyz="-0.0762 0 2E-05"/>
    <parent link="chassis"/>
    <child link="shell"/>
    <axis xyz="0 0 0"/>
  </joint>
  <gazebo reference="chassis">
    <mu1 value="0.0"/>
    <mu2 value="0.0"/>
    <kp value="1000000.0"/>
    <kd value="1.0"/>
  </gazebo>
  <gazebo reference="left_rear_wheel">
    <mu1 value="0.5"/>
    <mu2 value="0.5"/>
    <kp value="1000000.0"/>
    <kd value="1.0"/>
    <fdir1 value="1 0 0"/>
  </gazebo>
  <gazebo reference="right_rear_wheel">
    <mu1 value="0.5"/>
    <mu2 value="0.5"/>
    <kp value="1000000.0"/>
    <kd value="1.0"/>
    <fdir1 value="1 0 0"/>
  </gazebo>
  <gazebo reference="left_front_wheel">
    <mu1 value="0.5"/>
    <mu2 value="0.5"/>
    <kp value="1000000.0"/>
    <kd value="1.0"/>
    <fdir1 value="1 0 0"/>
  </gazebo>
  <gazebo reference="right_front_wheel">
    <mu1 value="0.5"/>
    <mu2 value="0.5"/>
    <kp value="1000000.0"/>
    <kd value="1.0"/>
    <fdir1 value="1 0 0"/>
  </gazebo>
  <gazebo reference="left_rear_wheel">
    <collision>
      <surface>
        <contact>
          <collide_bitmask>0x01</collide_bitmask>
        </contact>
      </surface>
    </collision>
  </gazebo>
  <gazebo reference="right_rear_wheel">
    <collision>
      <surface>
        <contact>
          <collide_bitmask>0x01</collide_bitmask>
        </contact>
      </surface>
    </collision>
  </gazebo>
  <gazebo reference="left_front_wheel">
    <collision>
      <surface>
        <contact>
          <collide_bitmask>0x01</collide_bitmask>
        </contact>
      </surface>
    </collision>
  </gazebo>
  <gazebo reference="right_front_wheel">
    <collision>
      <surface>
        <contact>
          <collide_bitmask>0x01</collide_bitmask>
        </contact>
      </surface>
    </collision>
  </gazebo>
  <gazebo reference="shell">
    <collision>
      <surface>
        <contact>
          <collide_bitmask>0x01</collide_bitmask>
        </contact>
      </surface>
    </collision>
  </gazebo>
  <gazebo reference="laser">
    <collision>
      <surface>
        <contact>
          <collide_bitmask>0x01</collide_bitmask>
        </contact>
      </surface>
    </collision>
  </gazebo>
  <gazebo>
    <plugin filename="libgazebo_ros_deepracer_drive.so" name="gazebo_ros_deepracer_drive">
      <update_rate>15.0</update_rate>
      <!-- Max absolute steer angle for tyre in radians-->
      <!-- Any cmd_vel angular z greater than this would be capped -->
      <max_steer>0.523599</max_steer>
      <!-- Max absolute linear speed in m/s -->
      <max_speed>4</max_speed>
      <!-- Radius of rear wheels, in meters -->
      <wheel_radius>0.03</wheel_radius>
      <!-- Distance between front and rear axles, in meters -->
      <wheel_base>0.164023</wheel_base>
      <!-- Distance between the wheels, in meters -->
      <wheel_separation>0.159202</wheel_separation>
      <publish_odom>true</publish_odom>
      <publish_odom_tf>true</publish_odom_tf>
      <odometry_frame>odom</odometry_frame>
      <robot_base_frame>base_link</robot_base_frame>
    </plugin>
  </gazebo>
  <ros2_control name="racecar" type="system">
    <hardware>
      <plugin>gazebo_ros2_control/GazeboSystem</plugin>
    </hardware>
    <joint name="left_rear_wheel_joint">
      <command_interface name="velocity"/>
      <state_interface name="velocity"/>
    </joint>
    <joint name="right_rear_wheel_joint">
      <command_interface name="velocity"/>
      <state_interface name="velocity"/>
    </joint>
    <joint name="left_front_wheel_joint">
      <command_interface name="velocity"/>
      <state_interface name="velocity"/>
    </joint>
    <joint name="right_front_wheel_joint">
      <command_interface name="velocity"/>
      <state_interface name="velocity"/>
    </joint>
    <joint name="left_steering_hinge_joint">
      <command_interface name="position">
      </command_interface>
      <state_interface name="position"/>
    </joint>
    <joint name="right_steering_hinge_joint">
      <command_interface name="position">
      </command_interface>
      <state_interface name="position"/>
    </joint>
  </ros2_control>
  <gazebo>
    <plugin filename="libgazebo_ros2_control.so" name="gazebo_ros2_control">
      <robot_param>robot_description</robot_param>
      <robot_param_node>robot_state_publisher</robot_param_node>
      <parameters>/home/chuismi/Desktop/robotica/cuarto/tfg/2022-tfg-luismiguel-lopez/tfg_ws/src/track_model/config/agent_control.yaml</parameters>
    </plugin>
  </gazebo>
  <gazebo reference="left_rear_wheel">
    <material>Gazebo/Black</material>
  </gazebo>
  <gazebo reference="right_rear_wheel">
    <material>Gazebo/Black</material>
  </gazebo>
  <gazebo reference="left_front_wheel">
    <material>Gazebo/Black</material>
  </gazebo>
  <gazebo reference="right_front_wheel">
    <material>Gazebo/Black</material>
  </gazebo>
  <gazebo reference="camera_link">
    <sensor name="zed_camera_left_sensor" type="camera">
      <pose>0 0 0 0 0 0</pose>
      <update_rate>15.0</update_rate>
      <camera name="zed_camera_left_camera">
        <horizontal_fov>1.13</horizontal_fov>
        <image>
          <width>640</width>
          <height>480</height>
          <format>R8G8B8</format>
        </image>
        <clip>
          <near>0.02</near>
          <far>300</far>
        </clip>
      </camera>
      <plugin filename="libgazebo_ros_camera.so" name="camera_controller">
        <alwaysOn>true</alwaysOn>
        <updateRate>60</updateRate>
        <cameraName>camera</cameraName>
        <imageTopicName>image</imageTopicName>
        <cameraInfoTopicName>camera_info</cameraInfoTopicName>
        <frameName>camera_link</frameName>
        <hackBaseline>0</hackBaseline>
        <!-- set this to 0.12 for the second camera -->
        <distortionK1>0.0</distortionK1>
        <distortionK2>0.0</distortionK2>
        <distortionK3>0.0</distortionK3>
        <distortionT1>0.0</distortionT1>
        <distortionT2>0.0</distortionT2>
      </plugin>
    </sensor>
  </gazebo>
  <gazebo reference="laser">
    <sensor name="hokuyo_sensor" type="ray">
      <pose>0 0 0 0 0 0</pose>
      <visualize>true</visualize>
      <update_rate>10</update_rate>
      <ray>
        <scan>
          <horizontal>
            <samples>600</samples>
            <resolution>1</resolution>
            <min_angle>-2.61799</min_angle>
            <max_angle>2.61799</max_angle>
          </horizontal>
        </scan>
        <range>
          <min>0.15</min>
          <max>10.0</max>
          <resolution>0.01</resolution>
        </range>
        <noise>
          <mean>0.0</mean>
          <stddev>0.01</stddev>
        </noise>
      </ray>
      <!--<plugin name="gazebo_ros_hokuyo_controller" filename="libgazebo_ros_laser.so">
        <topicName>/scan</topicName>
        <frameName>laser</frameName>
      </plugin>-->
      <plugin filename="libgazebo_ros_ray_sensor.so" name="rp_lidar">
        <ros>
          <!-- <namespace>/laser</namespace> -->
          <argument>~/out:=scan</argument>
        </ros>
        <output_type>sensor_msgs/LaserScan</output_type>
        <frame_name>laser</frame_name>
      </plugin>
    </sensor>
  </gazebo>
</robot>
